Workbook

Sheet COB
B1: WIP | C1: Fail | E1: COB
A2: WO | B2: Qty In | C2: Note | D2: Fill Target Start Time, Input/Output, Machine Used, Actual Start/End, and Fail ONLY | E2: RX DB | G2: RX Baking | I2: FSI DB | K2: FSI Baking | M2: TX-COS DB | O2: Die Visual Inspection | Q2: Dimension Test | S2: TX-COS Baking | U2: COB WB | W2: Die/Wire Inspection | Y2: Die/Wire Visual Inspection | AA2: TX Lens Coupling | AC2: COB Black Glue Fixing | AE2: COB Black Glue Baking | AG2: COB Visual Inspection | AI2: Yield
A3: 120011111 | B3: 20 | C3: NA | D3: Target UPH | E3: 16 | G3: 248 | I3: 51 | K3: 248 | M3: 23 | O3: 60 | Q3: 60 | S3: 248 | U3: 32 | W3: 16 | Y3: 60 | AA3: 4 | AC3: 40 | AE3: 248 | AG3: 60
D4: # Machine Used | E4: 1 | G4: 1 | I4: 1 | K4: 1 | M4: 1 | O4: 1 | Q4: 1 | S4: 1 | U4: 1 | W4: 1 | Y4: 1 | AA4: 1 | AC4: 1 | AE4: 1 | AG4: 1
D5: Expected Work Hours | E5: =(E10/(E3*E4))/24 -> 0.052083333 | G5: =2/24 -> 0.083333333 | I5: =(I10/(I3*I4))/24 -> 0.014705882 | K5: =2/24 -> 0.083333333 | M5: =(M10/(M3*M4))/24 -> 0.032608696 | O5: =(O10/(O3*O4))/24 -> 0.010416667 | Q5: =(Q10/(Q3*Q4))/24 -> 0.010416667 | S5: =2/24 -> 0.083333333 | U5: =(U10/(U3*U4))/24 -> 0.015625 | W5: =(W10/(W3*W4))/24 -> 0.015625 | Y5: =(Y10/(Y3*Y4))/24 -> 0.0041666667 | AA5: =(AA10/(AA3*AA4))/24 -> 0.0625 | AC5: =(AC10/(AC3*AC4))/24 -> 0.00625 | AE5: =2/24 -> 0.083333333 | AG5: =(AG10/(AG3*AG4))/24 -> 0.0041666667
D6: Target Start/End | E6: 46147.375 | F6: =E6+E5 -> 46147.427 | G6: 46147.417 | H6: =G6+G5 -> 46147.5 | I6: 46147.375 | J6: =I6+I5 -> 46147.39 | K6: 46147.375 | L6: =K6+K5 -> 46147.458 | M6: 46147.375 | N6: =M6+M5 -> 46147.408 | O6: 46147.375 | P6: =O6+O5 -> 46147.385 | Q6: 46147.375 | R6: =Q6+Q5 -> 46147.385 | S6: 46147.375 | T6: =S6+S5 -> 46147.458 | U6: 46147.375 | V6: =U6+U5 -> 46147.391 | W6: 46147.375 | X6: =W6+W5 -> 46147.391 | Y6: 46147.375 | Z6: =Y6+Y5 -> 46147.379 | AA6: 46147.375 | AB6: =AA6+AA5 -> 46147.438 | AC6: 46147.375 | AD6: =AC6+AC5 -> 46147.381 | AE6: 46147.375 | AF6: =AE6+AE5 -> 46147.458 | AG6: 46147.375 | AH6: =AG6+AG5 -> 46147.379
D7: Actual Start/End | E7: 46147.385 | F7: 46147.469
D8: Actual Work Hours | E8: =F7-E7 -> 0.083333333 | G8: =H7-G7 -> 0 | I8: =J7-I7 -> 0 | K8: =L7-K7 -> 0 | M8: =N7-M7 -> 0 | O8: =P7-O7 -> 0 | Q8: =R7-Q7 -> 0 | S8: =T7-S7 -> 0 | U8: =V7-U7 -> 0 | W8: =X7-W7 -> 0 | Y8: =Z7-Y7 -> 0 | AA8: =AB7-AA7 -> 0 | AC8: =AD7-AC7 -> 0 | AE8: =AF7-AE7 -> 0 | AG8: =AH7-AG7 -> 0
D9: Actual UPH | E9: =E10/((F7-E7)*24) -> 10 | G9: =G10/((H7-G7)*24) -> #DIV/0! | I9: =I10/((J7-I7)*24) -> #DIV/0! | K9: =K10/((L7-K7)*24) -> #DIV/0! | M9: =M10/((N7-M7)*24) -> #DIV/0! | O9: =O10/((P7-O7)*24) -> #DIV/0! | Q9: =Q10/((R7-Q7)*24) -> #DIV/0! | S9: =S10/((T7-S7)*24) -> #DIV/0! | U9: =U10/((V7-U7)*24) -> #DIV/0! | W9: =W10/((X7-W7)*24) -> #DIV/0! | Y9: =Y10/((Z7-Y7)*24) -> #DIV/0! | AA9: =AA10/((AB7-AA7)*24) -> #DIV/0! | AC9: =AC10/((AD7-AC7)*24) -> #DIV/0! | AE9: =AE10/((AF7-AE7)*24) -> #DIV/0! | AG9: =AG10/((AH7-AG7)*24) -> #DIV/0!
D10: WO InputOut | E10: 20 | F10: 18 | G10: 18 | H10: 18 | I10: 18 | J10: 18 | K10: 18 | L10: 18 | M10: 18 | N10: 15 | O10: 15 | P10: 15 | Q10: 15 | R10: 15 | S10: 15 | T10: 12 | U10: 12 | V10: 6 | W10: 6 | X10: 6 | Y10: 6 | Z10: 6 | AA10: 6 | AB10: 6 | AC10: 6 | AD10: 6 | AE10: 6 | AF10: 6 | AG10: 6 | AH10: 1 | AI10: =AH10/E10 -> 0.05
D11: WIP / Fail | E11: =E10-F10-F11 -> 0 | F11: 2 | G11: =G10-H10-H11 -> 0 | I11: =I10-J10-J11 -> 0 | K11: =K10-L10-L11 -> 0 | M11: =M10-N10-N11 -> 3 | O11: =O10-P10-P11 -> -2 | P11: 2 | Q11: =Q10-R10-R11 -> 0 | S11: =S10-T10-T11 -> 3 | U11: =U10-V10-V11 -> 6 | W11: =W10-X10-X11 -> 0 | Y11: =Y10-Z10-Z11 -> 0 | AA11: =AA10-AB10-AB11 -> 0 | AC11: =AC10-AD10-AD11 -> 0 | AE11: =AE10-AF10-AF11 -> 0 | AG11: =AG10-AH10-AH11 -> 5
D12: Yield | E12: =F10/E10 -> 0.9 | G12: =H10/G10 -> 1 | I12: =J10/I10 -> 1 | K12: =L10/K10 -> 1 | M12: =N10/M10 -> 0.83333333 | O12: =P10/O10 -> 1 | Q12: =R10/Q10 -> 1 | S12: =T10/S10 -> 0.8 | U12: =V10/U10 -> 0.5 | W12: =X10/W10 -> 1 | Y12: =Z10/Y10 -> 1 | AA12: =AB10/AA10 -> 1 | AC12: =AD10/AC10 -> 1 | AE12: =AF10/AE10 -> 1 | AG12: =AH10/AG10 -> 0.16666667
A13: 120011112 | B13: 20 | C13: NA | D13: Target UPH | E13: 16 | G13: 248 | I13: 51 | K13: 248 | M13: 23 | O13: 60 | Q13: 60 | S13: 248 | U13: 32 | W13: 16 | Y13: 60 | AA13: 4 | AC13: 40 | AE13: 248 | AG13: 60
D14: # Machine Used | E14: 1 | G14: 1 | I14: 1 | K14: 1 | M14: 1 | O14: 1 | Q14: 1 | S14: 1 | U14: 1 | W14: 1 | Y14: 1 | AA14: 1 | AC14: 1 | AE14: 1 | AG14: 1
D15: Expected Work Hours | E15: =(E20/(E13*E14))/24 -> 0.052083333 | G15: =2/24 -> 0.083333333 | I15: =(I20/(I13*I14))/24 -> 0.016339869 | K15: =2/24 -> 0.083333333 | M15: =(M20/(M13*M14))/24 -> 0.036231884 | O15: =(O20/(O13*O14))/24 -> 0.013888889 | Q15: =(Q20/(Q13*Q14))/24 -> 0.013888889 | S15: =2/24 -> 0.083333333 | U15: =(U20/(U13*U14))/24 -> 0.026041667 | W15: =(W20/(W13*W14))/24 -> 0.052083333 | Y15: =(Y20/(Y13*Y14))/24 -> 0.013888889 | AA15: =(AA20/(AA13*AA14))/24 -> 0.20833333 | AC15: =(AC20/(AC13*AC14))/24 -> 0.020833333 | AE15: =2/24 -> 0.083333333 | AG15: =(AG20/(AG13*AG14))/24 -> 0.013888889
D16: Target Start/End | E16: 46147.375 | F16: =E16+E15 -> 46147.427 | G16: 46147.375 | H16: =G16+G15 -> 46147.458 | I16: 46147.375 | J16: =I16+I15 -> 46147.391 | K16: 46147.375 | L16: =K16+K15 -> 46147.458 | M16: 46147.375 | N16: =M16+M15 -> 46147.411 | O16: 46147.375 | P16: =O16+O15 -> 46147.389 | Q16: 46147.375 | R16: =Q16+Q15 -> 46147.389 | S16: 46147.375 | T16: =S16+S15 -> 46147.458 | U16: 46147.375 | V16: =U16+U15 -> 46147.401 | W16: 46147.375 | X16: =W16+W15 -> 46147.427 | Y16: 46147.375 | Z16: =Y16+Y15 -> 46147.389 | AA16: 46147.375 | AB16: =AA16+AA15 -> 46147.583 | AC16: 46147.375 | AD16: =AC16+AC15 -> 46147.396 | AE16: 46147.375 | AF16: =AE16+AE15 -> 46147.458 | AG16: 46147.375 | AH16: =AG16+AG15 -> 46147.389
D17: Actual Start/End | E17: 46147.385 | F17: 46147.469
D18: Actual Work Hours | E18: =F17-E17 -> 0.083333333 | G18: =H17-G17 -> 0 | I18: =J17-I17 -> 0 | K18: =L17-K17 -> 0 | M18: =N17-M17 -> 0 | O18: =P17-O17 -> 0 | Q18: =R17-Q17 -> 0 | S18: =T17-S17 -> 0 | U18: =V17-U17 -> 0 | W18: =X17-W17 -> 0 | Y18: =Z17-Y17 -> 0 | AA18: =AB17-AA17 -> 0 | AC18: =AD17-AC17 -> 0 | AE18: =AF17-AE17 -> 0 | AG18: =AH17-AG17 -> 0
D19: Actual UPH | E19: =E20/((F17-E17)*24) -> 10 | G19: =G20/((H17-G17)*24) -> #DIV/0! | I19: =I20/((J17-I17)*24) -> #DIV/0! | K19: =K20/((L17-K17)*24) -> #DIV/0! | M19: =M20/((N17-M17)*24) -> #DIV/0! | O19: =O20/((P17-O17)*24) -> #DIV/0! | Q19: =Q20/((R17-Q17)*24) -> #DIV/0! | S19: =S20/((T17-S17)*24) -> #DIV/0! | U19: =U20/((V17-U17)*24) -> #DIV/0! | W19: =W20/((X17-W17)*24) -> #DIV/0! | Y19: =Y20/((Z17-Y17)*24) -> #DIV/0! | AA19: =AA20/((AB17-AA17)*24) -> #DIV/0! | AC19: =AC20/((AD17-AC17)*24) -> #DIV/0! | AE19: =AE20/((AF17-AE17)*24) -> #DIV/0! | AG19: =AG20/((AH17-AG17)*24) -> #DIV/0!
D20: WO In/Out | E20: 20 | F20: 20 | G20: 20 | H20: 20 | I20: 20 | J20: 20 | K20: 20 | L20: 20 | M20: 20 | N20: 20 | O20: 20 | P20: 20 | Q20: 20 | R20: 20 | S20: 20 | T20: 20 | U20: 20 | V20: 20 | W20: 20 | X20: 20 | Y20: 20 | Z20: 20 | AA20: 20 | AB20: 20 | AC20: 20 | AD20: 20 | AE20: 20 | AF20: 20 | AG20: 20 | AH20: 18 | AI20: =AH20/E20 -> 0.9
D21: WIP / Fail | E21: =E20-F20-F21 -> 0 | G21: =G20-H20-H21 -> 0 | I21: =I20-J20-J21 -> 0 | K21: =K20-L20-L21 -> 0 | M21: =M20-N20-N21 -> 0 | O21: =O20-P20-P21 -> -2 | P21: 2 | Q21: =Q20-R20-R21 -> 0 | S21: =S20-T20-T21 -> 0 | U21: =U20-V20-V21 -> 0 | W21: =W20-X20-X21 -> 0 | Y21: =Y20-Z20-Z21 -> 0 | AA21: =AA20-AB20-AB21 -> 0 | AC21: =AC20-AD20-AD21 -> 0 | AE21: =AE20-AF20-AF21 -> 0 | AG21: =AG20-AH20-AH21 -> 2
D22: Yield by Station | E22: =F20/E20 -> 1 | G22: =H20/G20 -> 1 | I22: =J20/I20 -> 1 | K22: =L20/K20 -> 1 | M22: =N20/M20 -> 1 | O22: =P20/O20 -> 1 | Q22: =R20/Q20 -> 1 | S22: =T20/S20 -> 1 | U22: =V20/U20 -> 1 | W22: =X20/W20 -> 1 | Y22: =Z20/Y20 -> 1 | AA22: =AB20/AA20 -> 1 | AC22: =AD20/AC20 -> 1 | AE22: =AF20/AE20 -> 1 | AG22: =AH20/AG20 -> 0.9
D23: Input/Output All WOs | E23: =SUM(E10,E20) -> 40 | F23: =SUM(F10,F20) -> 38 | G23: =SUM(G10,G20) -> 38 | H23: =SUM(H10,H20) -> 38 | I23: =SUM(I10,I20) -> 38 | J23: =SUM(J10,J20) -> 38 | K23: =SUM(K10,K20) -> 38 | L23: =SUM(L10,L20) -> 38 | ... AH23: =SUM(AH10,AH20) -> 19 | AI23: {=AVERAGE(IF(AI3:AI12<>0, AI3:AI12))} -> 0.05
D24: Yield by Station All WOs | E24: =F23/E23 -> 0.95 | G24: =H23/G23 -> 1 | I24: =J23/I23 -> 1 | K24: =L23/K23 -> 1 | M24: =N23/M23 -> 0.92105263 | O24: =P23/O23 -> 1 | Q24: =R23/Q23 -> 1 | S24: =T23/S23 -> 0.91428571 | U24: =V23/U23 -> 0.8125 | W24: =X23/W23 -> 1 | Y24: =Z23/Y23 -> 1 | AA24: =AB23/AA23 -> 1 | AC24: =AD23/AC23 -> 1 | AE24: =AF23/AE23 -> 1 | AG24: =AH23/AG23 -> 0.73076923

Sheet Module Assembly
A1: 100G | B1: 200G | C1: 400G | E1: COB
A2: WO | B2: Qty In | C2: Note | AU2: Yield
A3: 120048945 | B3: 20 | C3: 100G | D3: Target Date | E3: 46049 | G3: =WORKDAY.INTL(E3,1,11) -> 46050 | I3: =WORKDAY.INTL(G3,0,11) -> 46050 | K3: =WORKDAY.INTL(I3,0,11) -> 46050 | M3: =WORKDAY.INTL(K3,0,11) -> 46050 | O3: =WORKDAY.INTL(M3,1,11) -> 46051 | Q3: =WORKDAY.INTL(O3,0,11) -> 46051 | S3: =WORKDAY.INTL(Q3,0,11) -> 46051 | U3: =WORKDAY.INTL(S3,0,11) -> 46051 | W3: =WORKDAY.INTL(U3,0,11) -> 46051 | Y3: =WORKDAY.INTL(W3,1,11) -> 46052 | AA3: =WORKDAY.INTL(Y3,0,11) -> 46052 | AC3: =WORKDAY.INTL(AA3,1,11) -> 46053 | AE3: =WORKDAY.INTL(AC3,1,11) -> 46055 | AG3: =WORKDAY.INTL(AE3,0,11) -> 46055 | AI3: =WORKDAY.INTL(AG3,0,11) -> 46055 | AK3: =WORKDAY.INTL(AI3,0,11) -> 46055 | AM3: =WORKDAY.INTL(AK3,0,11) -> 46055 | AO3: =WORKDAY.INTL(AM3,1,11) -> 46056 | AQ3: =WORKDAY.INTL(AO3,0,11) -> 46056 | AS3: =WORKDAY.INTL(AQ3,0,11) -> 46056
D4: Actual Date | O4: 46056 | Q4: 46057 | S4: 46057 | U4: 46057 | W4: 46057 | Y4: 46058 | AA4: 46059 | AC4: 46062 | AE4: 46062 | AG4: 46063 | AI4: 46063 | AK4: 46064 | AM4: 46064 | AO4: 46065 | AQ4: 46065 | AS4: 46065
D5: WO In/Out | E5: 20 | F5: 20 | G5: 20 | H5: 20 | I5: 20 | J5: 20 | K5: =J5 -> 20 | L5: 20 | M5: 20 | N5: 20 | O5: 20 | P5: 18 | Q5: 18 | R5: 18 | S5: =R5 -> 18 | T5: 18 | U5: =T5 -> 18 | V5: 18 | W5: =V5 -> 18 | X5: =W5 -> 18 | Y5: =X5 -> 18 | Z5: =Y5 -> 18 | AA5: =Z5 -> 18 | AB5: =AA5 -> 18 | AC5: =AB5 -> 18 | AD5: =AC5 -> 18 | ... AT5: =AS5 -> 18 | AU5: =AT5/E5 -> 0.9
D6: Yield | E6: =F5/E5 -> 1 | G6: =H5/G5 -> 1 | I6: =J5/I5 -> 1 | K6: =L5/K5 -> 1 | M6: =N5/M5 -> 1 | O6: =P5/O5 -> 0.9 | Q6: =R5/Q5 -> 1 | S6: =T5/S5 -> 1 | U6: =V5/U5 -> 1 | W6: =X5/W5 -> 1 | Y6: =Z5/Y5 -> 1 | AA6: =AB5/AA5 -> 1 | AC6: =AD5/AC5 -> 1 | AE6: =AF5/AE5 -> 1 | AG6: =AH5/AG5 -> 1 | AI6: =AJ5/AI5 -> 1 | AK6: =AL5/AK5 -> 1 | AM6: =AN5/AM5 -> 1 | AO6: =AP5/AO5 -> 1 | AQ6: =AR5/AQ5 -> 1 | AS6: =AT5/AS5 -> 1
E8: =SUM(E5) -> 20 | F8: =SUM(F5) -> 20 | G8: =SUM(G5) -> 20 | H8: =SUM(H5) -> 20 | I8: =SUM(I5,#REF!,#REF!,#REF!,#REF!,#REF!,#REF!,#REF!,#REF!,#REF!,#REF!,#REF!,#REF!,#REF!,#REF!,#REF!,#REF!,#REF!,#REF!,#REF!,#REF!,#REF!,#REF!,#REF!,#REF!,#REF!,#REF!,#REF!) -> #REF! | J8: =SUM(J5,#REF!,#REF!,#REF!,#REF!,#REF!,#REF!,#REF!,#REF!,#REF!,#REF!,#REF!,#REF!,#REF!,#REF!,#REF!,#REF!,#REF!,#REF!,#REF!,#REF!,#REF!,#REF!,#REF!,#REF!,#REF!,#REF!,#REF!) -> #REF! | K8: =SUM(K5,#REF!,#REF!,#REF!,#REF!,#REF!,#REF!,#REF!,#REF!,#REF!,#REF!,#REF!,#REF!,#REF!,#REF!,#REF!,#REF!,#REF!,#REF!,#REF!,#REF!,#REF!,#REF!,#REF!,#REF!,#REF!,#REF!,#REF!) -> #REF! | L8: =SUM(L5,#REF!,#REF!,#REF!,#REF!,#REF!,#REF!,#REF!,#REF!,#REF!,#REF!,#REF!,#REF!,#REF!,#REF!,#REF!,#REF!,#REF!,#REF!,#REF!,#REF!,#REF!,#REF!,#REF!,#REF!,#REF!,#REF!,#REF!) -> #REF! | M8: =SUM(M5,#REF!,#REF!,#REF!,#REF!,#REF!,#REF!,#REF!,#REF!,#REF!,#REF!,#REF!,#REF!,#REF!,#REF!,#REF!,#REF!,#REF!,#REF!,#REF!,#REF!,#REF!,#REF!,#REF!,#REF!,#REF!,#REF!,#REF!) -> #REF! | N8: =SUM(N5,#REF!,#REF!,#REF!,#REF!,#REF!,#REF!,#REF!,#REF!,#REF!,#REF!,#REF!,#REF!,#REF!,#REF!,#REF!,#REF!,#REF!,#REF!,#REF!,#REF!,#REF!,#REF!,#REF!,#REF!,#REF!,#REF!,#REF!) -> #REF! | O8: =SUM(O5,#REF!,#REF!,#REF!,#REF!,#REF!,#REF!,#REF!,#REF!,#REF!,#REF!,#REF!,#REF!,#REF!,#REF!,#REF!,#REF!,#REF!,#REF!,#REF!,#REF!,#REF!,#REF!,#REF!,#REF!,#REF!,#REF!,#REF!) -> #REF! | P8: =SUM(P5,#REF!,#REF!,#REF!,#REF!,#REF!,#REF!,#REF!,#REF!,#REF!,#REF!,#REF!,#REF!,#REF!,#REF!,#REF!,#REF!,#REF!,#REF!,#REF!,#REF!,#REF!,#REF!,#REF!,#REF!,#REF!,#REF!,#REF!) -> #REF! | ... AT8: =SUM(AT5,#REF!,#REF!,#REF!,#REF!,#REF!,#REF!,#REF!,#REF!,#REF!,#REF!,#REF!,#REF!,#REF!,#REF!,#REF!,#REF!,#REF!,#REF!,#REF!,#REF!,#REF!,#REF!,#REF!,#REF!,#REF!,#REF!,#REF!) -> #REF! | AU8: {=AVERAGE(IF(AU3:AU6<>0, AU3:AU6))} -> 0.9
E9: =F8/E8 -> 1 | G9: =H8/G8 -> 1 | I9: =J8/I8 -> #REF! | K9: =L8/K8 -> #REF! | M9: =N8/M8 -> #REF! | O9: =P8/O8 -> #REF! | Q9: =R8/Q8 -> #REF! | S9: =T8/S8 -> #REF! | U9: =V8/U8 -> #REF! | W9: =X8/W8 -> #REF! | Y9: =Z8/Y8 -> #REF! | AA9: =AB8/AA8 -> #REF! | AC9: =AD8/AC8 -> #REF! | AE9: =AF8/AE8 -> #REF! | AG9: =AH8/AG8 -> #REF! | AI9: =AJ8/AI8 -> #REF! | AK9: =AL8/AK8 -> #REF! | AM9: =AN8/AM8 -> #REF! | AO9: =AP8/AO8 -> #REF! | AQ9: =AR8/AQ8 -> #REF! | AS9: =AT8/AS8 -> #REF!

Sheet AOC 400G WOs
A1: 100G | B1: 200G | C1: 400G | E1: AOC
A2: WO | B2: Qty In | C2: Note | E2: Start Runcard | G2: AOC Assembly All 1 | I2: AOC Assembly All 2 | K2: AOC Assembly All 3 | M2: AOC Assembly 1 | O2: AOC Assembly 2 | Q2: AOC Assembly 3 | S2: AOC Baking | U2: AOC 20TC | W2: AOC Post Test | Y2: TCBer Test | AA2: Symbol Error Test | AC2: ATS Test | AE2: Packet Loss Test | AG2: AOC Inspection | AI2: INVT PCS | AK2: Yield
A3: 120049067 | B3: 15 | C3: 400G | D3: Target Date | E3: 46055 | G3: =WORKDAY.INTL(E3,0,11) -> 46055 | I3: =WORKDAY.INTL(G3,0,11) -> 46055 | K3: =WORKDAY.INTL(I3,0,11) -> 46055 | M3: =WORKDAY.INTL(E3,0,11) -> 46055 | O3: =WORKDAY.INTL(M3,0,11) -> 46055 | Q3: =WORKDAY.INTL(O3,0,11) -> 46055 | S3: =WORKDAY.INTL(Q3,0,11) -> 46055 | U3: =WORKDAY.INTL(S3,0,11) -> 46055 | W3: =WORKDAY.INTL(U3,2,11) -> 46057 | Y3: =WORKDAY.INTL(W3,0,11) -> 46057 | AA3: =WORKDAY.INTL(Y3,1,11) -> 46058 | AC3: =WORKDAY.INTL(AA3,0,11) -> 46058 | AE3: =WORKDAY.INTL(AC3,0,11) -> 46058 | AG3: =WORKDAY.INTL(AE3,0,11) -> 46058 | AI3: =WORKDAY.INTL(AG3,0,11) -> 46058
D4: Actual Date | E4: 46057 | M4: 46057 | O4: 46057 | Q4: 46057 | S4: 46057 | U4: 46058 | W4: 46059 | Y4: 46060 | AA4: 46061 | AC4: 46062 | AE4: 46063 | AG4: 46063 | AI4: 46076
D5: WO In/Out | E5: 15 | F5: 15 | G5: 15 | H5: 15 | I5: 15 | J5: 15 | K5: 15 | L5: 15 | M5: 15 | N5: 15 | O5: =N5 -> 15 | P5: 15 | Q5: =P5 -> 15 | R5: 15 | S5: 15 | T5: 15 | U5: 15 | V5: 15 | W5: 15 | X5: 12 | Y5: 12 | Z5: 12 | AA5: 12 | AB5: 11 | AC5: 11 | AD5: 10 | AE5: 10 | AF5: 10 | AG5: 10 | AH5: 10 | AI5: 10 | AJ5: 10 | AK5: =AJ5/E5 -> 0.66666667
D6: Yield | E6: =F5/E5 -> 1 | G6: =H5/G5 -> 1 | I6: =J5/I5 -> 1 | K6: =L5/K5 -> 1 | M6: =N5/M5 -> 1 | O6: =P5/O5 -> 1 | Q6: =R5/Q5 -> 1 | S6: =T5/S5 -> 1 | U6: =V5/U5 -> 1 | W6: =X5/W5 -> 0.8 | Y6: =Z5/Y5 -> 1 | AA6: =AB5/AA5 -> 0.91666667 | AC6: =AD5/AC5 -> 0.90909091 | AE6: =AF5/AE5 -> 1 | AG6: =AH5/AG5 -> 1 | AI6: =AJ5/AI5 -> 1
A7: 120049068 | B7: 15 | C7: 400G | D7: Target Date | E7: 46056 | G7: =WORKDAY.INTL(E7,0,11) -> 46056 | I7: =WORKDAY.INTL(G7,0,11) -> 46056 | K7: =WORKDAY.INTL(I7,0,11) -> 46056 | M7: =WORKDAY.INTL(E7,0,11) -> 46056 | O7: =WORKDAY.INTL(M7,0,11) -> 46056 | Q7: =WORKDAY.INTL(O7,0,11) -> 46056 | S7: =WORKDAY.INTL(Q7,0,11) -> 46056 | U7: =WORKDAY.INTL(S7,0,11) -> 46056 | W7: =WORKDAY.INTL(U7,2,11) -> 46058 | Y7: =WORKDAY.INTL(W7,0,11) -> 46058 | AA7: =WORKDAY.INTL(Y7,1,11) -> 46059 | AC7: =WORKDAY.INTL(AA7,0,11) -> 46059 | AE7: =WORKDAY.INTL(AC7,0,11) -> 46059 | AG7: =WORKDAY.INTL(AE7,0,11) -> 46059 | AI7: =WORKDAY.INTL(AG7,0,11) -> 46059
D8: Actual Date | S8: 46058 | U8: 46059 | W8: 46062 | Y8: 46062 | AA8: 46062 | AC8: 46062 | AE8: 46063 | AG8: 46063 | AI8: 46076
D9: WO In/Out | E9: 15 | F9: 15 | G9: 15 | H9: 15 | I9: 15 | J9: 15 | K9: 15 | L9: 15 | M9: 15 | N9: 15 | O9: 15 | P9: 15 | Q9: 15 | R9: 15 | S9: 15 | T9: 15 | U9: 15 | V9: 15 | W9: 15 | X9: 12 | Y9: 12 | Z9: 11 | AA9: 11 | AB9: 11 | AC9: 11 | AD9: 10 | AE9: 10 | AF9: 10 | AG9: 10 | AH9: 10 | AI9: 10 | AJ9: 10 | AK9: =AJ9/E9 -> 0.66666667
D10: Yield | E10: =F9/E9 -> 1 | G10: =H9/G9 -> 1 | I10: =J9/I9 -> 1 | K10: =L9/K9 -> 1 | M10: =N9/M9 -> 1 | O10: =P9/O9 -> 1 | Q10: =R9/Q9 -> 1 | S10: =T9/S9 -> 1 | U10: =V9/U9 -> 1 | W10: =X9/W9 -> 0.8 | Y10: =Z9/Y9 -> 0.91666667 | AA10: =AB9/AA9 -> 1 | AC10: =AD9/AC9 -> 0.90909091 | AE10: =AF9/AE9 -> 1 | AG10: =AH9/AG9 -> 1 | AI10: =AJ9/AI9 -> 1
A11: 120049169 | B11: 15 | C11: 400G | D11: Target Date | E11: 46057 | G11: =WORKDAY.INTL(E11,0,11) -> 46057 | I11: =WORKDAY.INTL(G11,0,11) -> 46057 | K11: =WORKDAY.INTL(I11,0,11) -> 46057 | M11: =WORKDAY.INTL(E11,0,11) -> 46057 | O11: =WORKDAY.INTL(M11,0,11) -> 46057 | Q11: =WORKDAY.INTL(O11,0,11) -> 46057 | S11: =WORKDAY.INTL(Q11,0,11) -> 46057 | U11: =WORKDAY.INTL(S11,0,11) -> 46057 | W11: =WORKDAY.INTL(U11,2,11) -> 46059 | Y11: =WORKDAY.INTL(W11,0,11) -> 46059 | AA11: =WORKDAY.INTL(Y11,1,11) -> 46060 | AC11: =WORKDAY.INTL(AA11,0,11) -> 46060 | AE11: =WORKDAY.INTL(AC11,0,11) -> 46060 | AG11: =WORKDAY.INTL(AE11,0,11) -> 46060 | AI11: =WORKDAY.INTL(AG11,0,11) -> 46060
D12: Actual Date | S12: 46059 | U12: 46060 | W12: 46063 | Y12: 46063 | AA12: 46063 | AC12: 46063 | AE12: 46063 | AG12: 46064 | AI12: 46076
D13: WO In/Out | E13: 15 | F13: 15 | G13: 15 | H13: 15 | I13: 15 | J13: 15 | K13: 15 | L13: 15 | M13: 15 | N13: 15 | O13: 15 | P13: 15 | Q13: 15 | R13: 15 | S13: 15 | T13: 15 | U13: 15 | V13: 15 | W13: 15 | X13: 11 | Y13: 11 | Z13: 11 | AA13: 11 | AB13: 10 | AC13: 10 | AD13: 10 | AE13: 10 | AF13: 10 | AG13: 10 | AH13: 10 | AI13: 10 | AJ13: 10 | AK13: =AJ13/E13 -> 0.66666667
D14: Yield | E14: =F13/E13 -> 1 | G14: =H13/G13 -> 1 | I14: =J13/I13 -> 1 | K14: =L13/K13 -> 1 | M14: =N13/M13 -> 1 | O14: =P13/O13 -> 1 | Q14: =R13/Q13 -> 1 | S14: =T13/S13 -> 1 | U14: =V13/U13 -> 1 | W14: =X13/W13 -> 0.73333333 | Y14: =Z13/Y13 -> 1 | AA14: =AB13/AA13 -> 0.90909091 | AC14: =AD13/AC13 -> 1 | AE14: =AF13/AE13 -> 1 | AG14: =AH13/AG13 -> 1 | AI14: =AJ13/AI13 -> 1
A15: 120049170 | B15: 15 | C15: 400G | D15: Target Date | E15: 46058 | G15: =WORKDAY.INTL(E15,0,11) -> 46058 | I15: =WORKDAY.INTL(G15,0,11) -> 46058 | K15: =WORKDAY.INTL(I15,0,11) -> 46058 | M15: =WORKDAY.INTL(E15,0,11) -> 46058 | O15: =WORKDAY.INTL(M15,0,11) -> 46058 | Q15: =WORKDAY.INTL(O15,0,11) -> 46058 | S15: =WORKDAY.INTL(Q15,0,11) -> 46058 | U15: =WORKDAY.INTL(S15,0,11) -> 46058 | W15: =WORKDAY.INTL(U15,2,11) -> 46060 | Y15: =WORKDAY.INTL(W15,0,11) -> 46060 | AA15: =WORKDAY.INTL(Y15,1,11) -> 46062 | AC15: =WORKDAY.INTL(AA15,0,11) -> 46062 | AE15: =WORKDAY.INTL(AC15,0,11) -> 46062 | AG15: =WORKDAY.INTL(AE15,0,11) -> 46062 | AI15: =WORKDAY.INTL(AG15,0,11) -> 46062
D16: Actual Date | E16: 46058 | M16: 46059 | O16: 46059 | Q16: 46059 | S16: 46062 | U16: 46062 | W16: 46063 | Y16: 46063 | AA16: 46063 | AC16: 46063 | AE16: 46063 | AG16: 46064 | AI16: 46076
D17: WO In/Out | E17: 15 | F17: 15 | G17: 15 | H17: 15 | I17: 15 | J17: 11 | K17: 11 | L17: 11 | M17: 11 | N17: 11 | O17: 11 | P17: 11 | Q17: 11 | R17: 11 | S17: 11 | T17: 11 | U17: 11 | V17: 11 | W17: 11 | X17: 8 | Y17: 8 | Z17: 8 | AA17: 8 | AB17: 8 | AC17: 8 | AD17: 8 | AE17: 8 | AF17: 8 | AG17: 8 | AH17: 8 | AI17: 8 | AJ17: 8 | AK17: =AJ17/E17 -> 0.53333333
D18: Yield | E18: =F17/E17 -> 1 | G18: =H17/G17 -> 1 | I18: =J17/I17 -> 0.73333333 | K18: =L17/K17 -> 1 | M18: =N17/M17 -> 1 | O18: =P17/O17 -> 1 | Q18: =R17/Q17 -> 1 | S18: =T17/S17 -> 1 | U18: =V17/U17 -> 1 | W18: =X17/W17 -> 0.72727273 | Y18: =Z17/Y17 -> 1 | AA18: =AB17/AA17 -> 1 | AC18: =AD17/AC17 -> 1 | AE18: =AF17/AE17 -> 1 | AG18: =AH17/AG17 -> 1 | AI18: =AJ17/AI17 -> 1
A19: 120049430 | B19: 30 | C19: 400G | D19: Target Date | E19: 46063 | G19: =WORKDAY.INTL(E19,0,11) -> 46063 | I19: =WORKDAY.INTL(G19,0,11) -> 46063 | K19: =WORKDAY.INTL(I19,0,11) -> 46063 | M19: =WORKDAY.INTL(E19,0,11) -> 46063 | O19: =WORKDAY.INTL(M19,0,11) -> 46063 | Q19: =WORKDAY.INTL(O19,0,11) -> 46063 | S19: =WORKDAY.INTL(Q19,0,11) -> 46063 | U19: =WORKDAY.INTL(S19,0,11) -> 46063 | W19: =WORKDAY.INTL(U19,2,11) -> 46065 | Y19: =WORKDAY.INTL(W19,0,11) -> 46065 | AA19: =WORKDAY.INTL(Y19,1,11) -> 46066 | AC19: =WORKDAY.INTL(AA19,0,11) -> 46066 | AE19: =WORKDAY.INTL(AC19,0,11) -> 46066 | AG19: =WORKDAY.INTL(AE19,0,11) -> 46066 | AI19: =WORKDAY.INTL(AG19,0,11) -> 46066
D20: Actual Date | E20: 46062 | M20: 46063 | O20: 46063 | Q20: 46063 | S20: 46063 | U20: 46064 | W20: 46069 | Y20: 46069 | AA20: 46070 | AC20: 46070 | AE20: 46070 | AG20: 46071 | AI20: 46077
D21: WO In/Out | E21: 30 | F21: 30 | G21: 30 | H21: 30 | I21: 30 | J21: 26 | K21: 26 | L21: 26 | M21: 26 | N21: 26 | O21: 26 | P21: 26 | Q21: 26 | R21: 26 | S21: 26 | T21: 26 | U21: 26 | V21: 26 | W21: 26 | X21: 21 | Y21: 21 | Z21: 21 | AA21: 21 | AB21: 20 | AC21: 20 | AD21: 16 | AE21: 16 | AF21: 16 | AG21: 16 | AH21: 16 | AI21: 16 | AJ21: 16 | AK21: =AJ21/E21 -> 0.53333333
D22: Yield | E22: =F21/E21 -> 1 | G22: =H21/G21 -> 1 | I22: =J21/I21 -> 0.86666667 | K22: =L21/K21 -> 1 | M22: =N21/M21 -> 1 | O22: =P21/O21 -> 1 | Q22: =R21/Q21 -> 1 | S22: =T21/S21 -> 1 | U22: =V21/U21 -> 1 | W22: =X21/W21 -> 0.80769231 | Y22: =Z21/Y21 -> 1 | AA22: =AB21/AA21 -> 0.95238095 | AC22: =AD21/AC21 -> 0.8 | AE22: =AF21/AE21 -> 1 | AG22: =AH21/AG21 -> 1 | AI22: =AJ21/AI21 -> 1
A23: 120049431 | B23: 30 | C23: 400G | D23: Target Date | E23: 46064 | G23: =WORKDAY.INTL(E23,0,11) -> 46064 | I23: =WORKDAY.INTL(G23,0,11) -> 46064 | K23: =WORKDAY.INTL(I23,0,11) -> 46064 | M23: =WORKDAY.INTL(E23,0,11) -> 46064 | O23: =WORKDAY.INTL(M23,0,11) -> 46064 | Q23: =WORKDAY.INTL(O23,0,11) -> 46064 | S23: =WORKDAY.INTL(Q23,0,11) -> 46064 | U23: =WORKDAY.INTL(S23,0,11) -> 46064 | W23: =WORKDAY.INTL(U23,2,11) -> 46066 | Y23: =WORKDAY.INTL(W23,0,11) -> 46066 | AA23: =WORKDAY.INTL(Y23,1,11) -> 46067 | AC23: =WORKDAY.INTL(AA23,0,11) -> 46067 | AE23: =WORKDAY.INTL(AC23,0,11) -> 46067 | AG23: =WORKDAY.INTL(AE23,0,11) -> 46067 | AI23: =WORKDAY.INTL(AG23,0,11) -> 46067
D24: Actual Date | E24: 46062 | M24: 46064 | O24: 46064 | Q24: 46064 | S24: 46064 | U24: 46064 | W24: 46066 | Y24: 46069 | AA24: 46069 | AC24: 46069 | AE24: 46070 | AG24: 46071 | AI24: 46077
D25: WO In/Out | E25: 30 | F25: 30 | G25: 30 | H25: 30 | I25: 30 | J25: 25 | K25: 25 | L25: 25 | M25: 25 | N25: 25 | O25: 25 | P25: 25 | Q25: 25 | R25: 25 | S25: 25 | T25: 24 | U25: 24 | V25: 24 | W25: 24 | X25: 12 | Y25: 12 | Z25: 12 | AA25: 12 | AB25: 12 | AC25: 12 | AD25: 12 | AE25: 12 | AF25: 12 | AG25: 12 | AH25: 12 | AI25: 12 | AJ25: 12 | AK25: =AJ25/E25 -> 0.4
D26: Yield | E26: =F25/E25 -> 1 | G26: =H25/G25 -> 1 | I26: =J25/I25 -> 0.83333333 | K26: =L25/K25 -> 1 | M26: =N25/M25 -> 1 | O26: =P25/O25 -> 1 | Q26: =R25/Q25 -> 1 | S26: =T25/S25 -> 0.96 | U26: =V25/U25 -> 1 | W26: =X25/W25 -> 0.5 | Y26: =Z25/Y25 -> 1 | AA26: =AB25/AA25 -> 1 | AC26: =AD25/AC25 -> 1 | AE26: =AF25/AE25 -> 1 | AG26: =AH25/AG25 -> 1 | AI26: =AJ25/AI25 -> 1
A27: 120049432 | B27: 30 | C27: 400G | D27: Target Date | E27: 46065 | G27: =WORKDAY.INTL(E27,0,11) -> 46065 | I27: =WORKDAY.INTL(G27,0,11) -> 46065 | K27: =WORKDAY.INTL(I27,0,11) -> 46065 | M27: =WORKDAY.INTL(E27,0,11) -> 46065 | O27: =WORKDAY.INTL(M27,0,11) -> 46065 | Q27: =WORKDAY.INTL(O27,0,11) -> 46065 | S27: =WORKDAY.INTL(Q27,0,11) -> 46065 | U27: =WORKDAY.INTL(S27,0,11) -> 46065 | W27: =WORKDAY.INTL(U27,2,11) -> 46067 | Y27: =WORKDAY.INTL(W27,0,11) -> 46067 | AA27: =WORKDAY.INTL(Y27,1,11) -> 46069 | AC27: =WORKDAY.INTL(AA27,0,11) -> 46069 | AE27: =WORKDAY.INTL(AC27,0,11) -> 46069 | AG27: =WORKDAY.INTL(AE27,0,11) -> 46069 | AI27: =WORKDAY.INTL(AG27,0,11) -> 46069
D28: Actual Date | E28: 46065 | M28: 46066 | O28: 46066 | Q28: 46066 | S28: 46066 | U28: 46069 | W28: 46070 | Y28: 46070 | AA28: 46070 | AC28: 46070 | AE28: 46071 | AG28: 46071 | AI28: 46077
D29: WO In/Out | E29: 30 | F29: 30 | G29: 30 | H29: 30 | I29: 30 | J29: 29 | K29: 29 | L29: 29 | M29: 29 | N29: 29 | O29: 29 | P29: 29 | Q29: 29 | R29: 29 | S29: 29 | T29: 29 | U29: 29 | V29: 29 | W29: 29 | X29: 20 | Y29: 20 | Z29: 18 | AA29: 18 | AB29: 16 | AC29: 16 | AD29: 14 | AE29: 14 | AF29: 13 | AG29: 13 | AH29: 12 | AI29: 12 | AJ29: 12 | AK29: =AJ29/E29 -> 0.4
D30: Yield | E30: =F29/E29 -> 1 | G30: =H29/G29 -> 1 | I30: =J29/I29 -> 0.96666667 | K30: =L29/K29 -> 1 | M30: =N29/M29 -> 1 | O30: =P29/O29 -> 1 | Q30: =R29/Q29 -> 1 | S30: =T29/S29 -> 1 | U30: =V29/U29 -> 1 | W30: =X29/W29 -> 0.68965517 | Y30: =Z29/Y29 -> 0.9 | AA30: =AB29/AA29 -> 0.88888889 | AC30: =AD29/AC29 -> 0.875 | AE30: =AF29/AE29 -> 0.92857143 | AG30: =AH29/AG29 -> 0.92307692 | AI30: =AJ29/AI29 -> 1
A31: 120049433 | B31: 30 | C31: 400G | D31: Target Date | E31: 46066 | G31: =WORKDAY.INTL(E31,0,11) -> 46066 | I31: =WORKDAY.INTL(G31,0,11) -> 46066 | K31: =WORKDAY.INTL(I31,0,11) -> 46066 | M31: =WORKDAY.INTL(E31,0,11) -> 46066 | O31: =WORKDAY.INTL(M31,0,11) -> 46066 | Q31: =WORKDAY.INTL(O31,0,11) -> 46066 | S31: =WORKDAY.INTL(Q31,0,11) -> 46066 | U31: =WORKDAY.INTL(S31,0,11) -> 46066 | W31: =WORKDAY.INTL(U31,2,11) -> 46069 | Y31: =WORKDAY.INTL(W31,0,11) -> 46069 | AA31: =WORKDAY.INTL(Y31,1,11) -> 46070 | AC31: =WORKDAY.INTL(AA31,0,11) -> 46070 | AE31: =WORKDAY.INTL(AC31,0,11) -> 46070 | AG31: =WORKDAY.INTL(AE31,0,11) -> 46070 | AI31: =WORKDAY.INTL(AG31,0,11) -> 46070
D32: Actual Date | E32: 46066 | M32: 46066 | O32: 46066 | Q32: 46066 | S32: 46069 | U32: 46070 | W32: 46072 | Y32: 46072 | AA32: 46073 | AC32: 46073 | AE32: 46073 | AG32: 46076 | AI32: 46077
D33: WO In/Out | E33: 30 | F33: 30 | G33: 30 | H33: 30 | I33: 30 | J33: 28 | K33: 28 | L33: 28 | M33: 28 | N33: 28 | O33: 28 | P33: 28 | Q33: 28 | R33: 28 | S33: 28 | T33: 26 | U33: 26 | V33: 26 | W33: 26 | X33: 20 | Y33: 20 | Z33: 17 | AA33: 17 | AB33: 16 | AC33: 16 | AD33: 14 | AE33: 14 | AF33: 4 | AG33: 4 | AH33: 4 | AI33: 4 | AJ33: 4 | AK33: =AJ33/E33 -> 0.13333333
D34: Yield | E34: =F33/E33 -> 1 | G34: =H33/G33 -> 1 | I34: =J33/I33 -> 0.93333333 | K34: =L33/K33 -> 1 | M34: =N33/M33 -> 1 | O34: =P33/O33 -> 1 | Q34: =R33/Q33 -> 1 | S34: =T33/S33 -> 0.92857143 | U34: =V33/U33 -> 1 | W34: =X33/W33 -> 0.76923077 | Y34: =Z33/Y33 -> 0.85 | AA34: =AB33/AA33 -> 0.94117647 | AC34: =AD33/AC33 -> 0.875 | AE34: =AF33/AE33 -> 0.28571429 | AG34: =AH33/AG33 -> 1 | AI34: =AJ33/AI33 -> 1
A35: 120049434 | B35: 30 | C35: 400G | D35: Target Date | E35: 46069 | G35: =WORKDAY.INTL(E35,0,11) -> 46069 | I35: =WORKDAY.INTL(G35,0,11) -> 46069 | K35: =WORKDAY.INTL(I35,0,11) -> 46069 | M35: =WORKDAY.INTL(E35,0,11) -> 46069 | O35: =WORKDAY.INTL(M35,0,11) -> 46069 | Q35: =WORKDAY.INTL(O35,0,11) -> 46069 | S35: =WORKDAY.INTL(Q35,0,11) -> 46069 | U35: =WORKDAY.INTL(S35,0,11) -> 46069 | W35: =WORKDAY.INTL(U35,2,11) -> 46071 | Y35: =WORKDAY.INTL(W35,0,11) -> 46071 | AA35: =WORKDAY.INTL(Y35,1,11) -> 46072 | AC35: =WORKDAY.INTL(AA35,0,11) -> 46072 | AE35: =WORKDAY.INTL(AC35,0,11) -> 46072 | AG35: =WORKDAY.INTL(AE35,0,11) -> 46072 | AI35: =WORKDAY.INTL(AG35,0,11) -> 46072
D36: Actual Date | E36: 46069 | M36: 46069 | O36: 46069 | Q36: 46069 | S36: 46070 | U36: 46071 | W36: 46072 | Y36: 46072 | AA36: 46073 | AC36: 46073 | AE36: 46073 | AG36: 46076 | AI36: 46077
D37: WO In/Out | E37: 30 | F37: 30 | G37: 30 | H37: 30 | I37: 30 | J37: 30 | K37: 30 | L37: 30 | M37: 30 | N37: 30 | O37: 30 | P37: 30 | Q37: 30 | R37: 30 | S37: 30 | T37: 30 | U37: 30 | V37: 30 | W37: 30 | X37: 19 | Y37: 19 | Z37: 17 | AA37: 17 | AB37: 17 | AC37: 17 | AD37: 12 | AE37: 12 | AF37: 12 | AG37: 12 | AH37: 12 | AI37: 12 | AJ37: 12 | AK37: =AJ37/E37 -> 0.4
D38: Yield | E38: =F37/E37 -> 1 | G38: =H37/G37 -> 1 | I38: =J37/I37 -> 1 | K38: =L37/K37 -> 1 | M38: =N37/M37 -> 1 | O38: =P37/O37 -> 1 | Q38: =R37/Q37 -> 1 | S38: =T37/S37 -> 1 | U38: =V37/U37 -> 1 | W38: =X37/W37 -> 0.63333333 | Y38: =Z37/Y37 -> 0.89473684 | AA38: =AB37/AA37 -> 1 | AC38: =AD37/AC37 -> 0.70588235 | AE38: =AF37/AE37 -> 1 | AG38: =AH37/AG37 -> 1 | AI38: =AJ37/AI37 -> 1
A39: 120049852 | B39: 20 | C39: 400G | D39: Target Date | E39: 46072 | G39: =WORKDAY.INTL(E39,0,11) -> 46072 | I39: =WORKDAY.INTL(G39,0,11) -> 46072 | K39: =WORKDAY.INTL(I39,0,11) -> 46072 | M39: =WORKDAY.INTL(E39,0,11) -> 46072 | O39: =WORKDAY.INTL(M39,0,11) -> 46072 | Q39: =WORKDAY.INTL(O39,0,11) -> 46072 | S39: =WORKDAY.INTL(Q39,0,11) -> 46072 | U39: =WORKDAY.INTL(S39,0,11) -> 46072 | W39: =WORKDAY.INTL(U39,2,11) -> 46074 | Y39: =WORKDAY.INTL(W39,0,11) -> 46074 | AA39: =WORKDAY.INTL(Y39,1,11) -> 46076 | AC39: =WORKDAY.INTL(AA39,0,11) -> 46076 | AE39: =WORKDAY.INTL(AC39,0,11) -> 46076 | AG39: =WORKDAY.INTL(AE39,0,11) -> 46076 | AI39: =WORKDAY.INTL(AG39,0,11) -> 46076
D40: Actual Date | E40: 46072 | M40: 46072 | O40: 46072 | Q40: 46072 | S40: 46072 | U40: 46073 | W40: 46073 | Y40: 46076 | AA40: 46077 | AC40: 46079 | AE40: 46080 | AG40: 46083 | AI40: 46085
...

Sheet MSFT Orders Summary
A1: Process | B1: Station | C1: Input | D1: Output | E1: WIP | F1: Repair | G1: Fixed | H1: Scrapped | I1: FPY | J1: Overall Yield
A2: COB 100G & 200G | B2: FW Writing | C2: =COB!E23 -> 40 | D2: =COB!F23 -> 38 | E2: =C2-D2-F2 -> 2 | F2: 0 | H2: 0 | I2: =(D2+E2-F2)/C2 -> 1 | J2: =(D2+E2-G2)/C2 -> 1
B3: Plasma Cleaning | C3: =COB!G23 -> 38 | D3: =COB!H23 -> 38 | E3: =C3-D3-F3 -> 0 | F3: 0 | H3: 0 | I3: =(D3+E3-F3)/C3 -> 1 | J3: =(D3+E3-G3)/C3 -> 1
B4: IC Die Bonding | C4: =COB!I23 -> 38 | D4: =COB!J23 -> 38 | E4: =C4-D4-F4 -> 0 | F4: 0 | H4: 0 | I4: =(D4+E4-F4)/C4 -> 1 | J4: =(D4+E4-G4)/C4 -> 1
B5: IC Size Check | C5: =COB!K23 -> 38 | D5: =COB!L23 -> 38 | E5: =C5-D5-F5 -> 0 | F5: 0 | H5: 0 | I5: =(D5+E5-F5)/C5 -> 1 | J5: =(D5+E5-G5)/C5 -> 1
B6: Baking H20S | C6: =COB!M23 -> 38 | D6: =COB!N23 -> 35 | E6: =C6-D6-F6 -> 3 | F6: 0 | H6: 0 | I6: =(D6+E6-F6)/C6 -> 1 | J6: =(D6+E6-G6)/C6 -> 1
B7: Wire Bonding | C7: =COB!O23 -> 35 | D7: =COB!P23 -> 35 | E7: 2 | F7: 12 | H7: 12 | I7: =(D7+E7-F7)/C7 -> 0.71428571 | J7: =(D7+E7-G7)/C7 -> 1.0571429
B8: Appearance Inspection | C8: =COB!Q23 -> 35 | D8: =COB!R23 -> 35 | E8: =C8-D8-F8 -> 0 | F8: 0 | H8: 0 | I8: =(D8+E8-F8)/C8 -> 1 | J8: =(D8+E8-G8)/C8 -> 1
B9: QA COB IPQC | C9: =COB!S23 -> 35 | D9: =COB!T23 -> 32 | E9: =C9-D9-F9 -> 3 | F9: 0 | H9: 0 | I9: =(D9+E9-F9)/C9 -> 1 | J9: =(D9+E9-G9)/C9 -> 1
B10: Burn-in Before Test | C10: =COB!U23 -> 32 | D10: =COB!V23 -> 26 | E10: =C10-D10-F10 -> 6 | F10: 0 | H10: 0 | I10: =(D10+E10-F10)/C10 -> 1 | J10: =(D10+E10-G10)/C10 -> 1
B11: COB Burn-In 1 | C11: =COB!W23 -> 26 | D11: =COB!X23 -> 26 | E11: =C11-D11-F11 -> 0 | F11: 0 | H11: 0 | I11: =(D11+E11-F11)/C11 -> 1 | J11: =(D11+E11-G11)/C11 -> 1
B12: Burn-in Pre Test | C12: =COB!Y23 -> 26 | D12: =COB!Z23 -> 26 | E12: =C12-D12-F12 -> 0 | F12: 0 | H12: 0 | I12: =(D12+E12-F12)/C12 -> 1 | J12: =(D12+E12-G12)/C12 -> 1
B13: COB Burn-In 2 | C13: =COB!AA23 -> 26 | D13: =COB!AB23 -> 26 | E13: =C13-D13-F13 -> 0 | F13: 0 | H13: 0 | I13: =(D13+E13-F13)/C13 -> 1 | J13: =(D13+E13-G13)/C13 -> 1
B14: Burn-in Post Test | C14: =COB!AC23 -> 26 | D14: =COB!AD23 -> 26 | E14: =C14-D14-F14 -> 0 | F14: 0 | H14: 0 | I14: =(D14+E14-F14)/C14 -> 1 | J14: =(D14+E14-G14)/C14 -> 1
B15: Lens Coupling | C15: =COB!AE23 -> 26 | D15: =COB!AF23 -> 26 | E15: =C15-D15-F15 -> 0 | F15: 0 | H15: 0 | I15: =(D15+E15-F15)/C15 -> 1 | J15: =(D15+E15-G15)/C15 -> 1
B16: UV Curing | C16: =COB!#REF! -> #REF! | D16: =COB!#REF! -> #REF! | E16: =C16-D16-F16 -> #REF! | F16: 0 | H16: 0 | I16: =(D16+E16-F16)/C16 -> #REF! | J16: =(D16+E16-G16)/C16 -> #REF!
B17: DP-190 | C17: =COB!#REF! -> #REF! | D17: =COB!#REF! -> #REF! | E17: =C17-D17-F17 -> #REF! | F17: 0 | H17: 0 | I17: =(D17+E17-F17)/C17 -> #REF! | J17: =(D17+E17-G17)/C17 -> #REF!
B18: BF-4 | C18: =COB!#REF! -> #REF! | D18: =COB!#REF! -> #REF! | E18: =C18-D18-F18 -> #REF! | F18: 0 | H18: 0 | I18: =(D18+E18-F18)/C18 -> #REF! | J18: =(D18+E18-G18)/C18 -> #REF!
B19: Baking BF-4 | C19: =COB!#REF! -> #REF! | D19: =COB!#REF! -> #REF! | E19: =C19-D19-F19 -> #REF! | F19: 0 | H19: 0 | I19: =(D19+E19-F19)/C19 -> #REF! | J19: =(D19+E19-G19)/C19 -> #REF!
B20: COB Inspection | C20: =COB!#REF! -> #REF! | D20: =COB!#REF! -> #REF! | E20: =C20-D20-F20 -> #REF! | F20: 9 | H20: 9 | I20: =(D20+E20-F20)/C20 -> #REF! | J20: =(D20+E20-G20)/C20 -> #REF!
B21: QA COB OQC | C21: =COB!#REF! -> #REF! | D21: =COB!#REF! -> #REF! | E21: =C21-D21-F21 -> #REF! | F21: 0 | H21: 0 | I21: =(D21+E21-F21)/C21 -> #REF! | J21: =(D21+E21-G21)/C21 -> #REF!
B22: INVT | C22: =COB!#REF! -> #REF! | D22: =COB!#REF! -> #REF! | E22: =C22-D22-F22 -> #REF! | F22: 0 | H22: 0 | I22: =(D22+E22-F22)/C22 -> #REF! | J22: =(D22+E22-G22)/C22 -> #REF!
B23: Total Volume | C23: =SUM(C2:C22) -> #REF! | D23: =SUM(D2:D22) -> #REF! | E23: =SUM(E2:E22) -> #REF! | F23: =SUM(F2:F22) -> 21 | H23: =SUM(H2:H22) -> 21 | I23: =(D23+E23-F23)/C23 -> #REF! | J23: =(D23+E23-G23)/C23 -> #REF!
B24: Total Yield | C24: =C2 -> 40 | D24: =D22 -> #REF! | E24: =SUM(E2:E22) -> #REF! | F24: =SUM(F2:F22) -> 21 | H24: =SUM(H2:H22) -> 21 | I24: =(D24+E24-F24)/C24 -> #REF! | J24: =(D24+E24-G24)/C24 -> #REF!
A25: AOC 400G | B25: Start Runcard | C25: ='AOC 400G WOs'!E91 -> 429 | D25: ='AOC 400G WOs'!F91 -> 429 | E25: =C25-D25-F25 -> 0 | H25: 0 | I25: =(D25+E25-F25)/C25 -> 1 | J25: =(D25+E25-G25)/C25 -> 1
B26: AOC Assembly All 1 | C26: ='AOC 400G WOs'!G91 -> 429 | D26: ='AOC 400G WOs'!H91 -> 429 | E26: =C26-D26-F26 -> 0 | I26: =(D26+E26-F26)/C26 -> 1 | J26: =(D26+E26-G26)/C26 -> 1
B27: AOC Assembly All 2 | C27: ='AOC 400G WOs'!I91 -> 429 | D27: ='AOC 400G WOs'!J91 -> 408 | E27: =C27-D27-F27 -> 5 | F27: 16 | G27: 0 | H27: 16 | I27: =(D27+E27-F27)/C27 -> 0.92540793 | J27: =(D27+E27-G27)/C27 -> 0.96270396
B28: AOC Assembly All 3 | C28: ='AOC 400G WOs'!K91 -> 408 | D28: ='AOC 400G WOs'!L91 -> 408 | E28: =C28-D28-F28 -> 0 | I28: =(D28+E28-F28)/C28 -> 1 | J28: =(D28+E28-G28)/C28 -> 1
B29: AOC Assembly 1 | C29: ='AOC 400G WOs'!M91 -> 408 | D29: ='AOC 400G WOs'!N91 -> 408 | E29: =C29-D29-F29 -> 0 | H29: 0 | I29: =(D29+E29-F29)/C29 -> 1 | J29: =(D29+E29-G29)/C29 -> 1
B30: AOC Assembly 2 | C30: ='AOC 400G WOs'!O91 -> 408 | D30: ='AOC 400G WOs'!P91 -> 407 | E30: =C30-D30-F30 -> 1 | H30: 0 | I30: =(D30+E30-F30)/C30 -> 1 | J30: =(D30+E30-G30)/C30 -> 1
B31: AOC Assembly 3 | C31: ='AOC 400G WOs'!Q91 -> 407 | D31: ='AOC 400G WOs'!R91 -> 407 | E31: =C31-D31-F31 -> 0 | H31: 0 | I31: =(D31+E31-F31)/C31 -> 1 | J31: =(D31+E31-G31)/C31 -> 1
B32: AOC Baking | C32: ='AOC 400G WOs'!S91 -> 407 | D32: ='AOC 400G WOs'!T91 -> 404 | E32: =C32-D32-F32 -> 0 | F32: 3 | H32: 3 | I32: =(D32+E32-F32)/C32 -> 0.98525799 | J32: =(D32+E32-G32)/C32 -> 0.99262899
B33: AOC 20TC | C33: ='AOC 400G WOs'!U91 -> 389 | D33: ='AOC 400G WOs'!V91 -> 381 | E33: =C33-D33-F33 -> 8 | H33: 0 | I33: =(D33+E33-F33)/C33 -> 1 | J33: =(D33+E33-G33)/C33 -> 1
B34: AOC Post Test | C34: ='AOC 400G WOs'!W91 -> 381 | D34: ='AOC 400G WOs'!X91 -> 270 | E34: =C34-D34-F34 -> 51 | F34: 60 | H34: 60 | I34: =(D34+E34-F34)/C34 -> 0.68503937 | J34: =(D34+E34-G34)/C34 -> 0.84251969
B35: TCBer Test | C35: ='AOC 400G WOs'!Y91 -> 270 | D35: ='AOC 400G WOs'!Z91 -> 226 | E35: =C35-D35-F35 -> 38 | F35: 6 | H35: 0 | I35: =(D35+E35-F35)/C35 -> 0.95555556 | J35: =(D35+E35-G35)/C35 -> 0.97777778
B36: Symbol Error Test | C36: ='AOC 400G WOs'!AA91 -> 226 | D36: ='AOC 400G WOs'!AB91 -> 215 | E36: =C36-D36-F36 -> 5 | F36: 6 | H36: 0 | I36: =(D36+E36-F36)/C36 -> 0.94690265 | J36: =(D36+E36-G36)/C36 -> 0.97345133
B37: ATS Test | C37: ='AOC 400G WOs'!AC91 -> 215 | D37: ='AOC 400G WOs'!AD91 -> 178 | E37: =C37-D37-F37 -> 37 | H37: 0 | I37: =(D37+E37-F37)/C37 -> 1 | J37: =(D37+E37-G37)/C37 -> 1
B38: Packet Loss Test | C38: ='AOC 400G WOs'!AE91 -> 178 | D38: ='AOC 400G WOs'!AF91 -> 157 | E38: =C38-D38-F38 -> 21 | H38: 0 | I38: =(D38+E38-F38)/C38 -> 1 | J38: =(D38+E38-G38)/C38 -> 1
B39: AOC Inspection | C39: ='AOC 400G WOs'!AG91 -> 157 | D39: ='AOC 400G WOs'!AH91 -> 132 | E39: =C39-D39-F39 -> 23 | F39: 2 | H39: 0 | I39: =(D39+E39-F39)/C39 -> 0.97452229 | J39: =(D39+E39-G39)/C39 -> 0.98726115
B40: INVT PCS | C40: ='AOC 400G WOs'!AI91 -> 132 | D40: ='AOC 400G WOs'!AJ91 -> 118 | E40: =C40-D40-F40 -> 14 | H40: 0 | I40: =(D40+E40-F40)/C40 -> 1 | J40: =(D40+E40-G40)/C40 -> 1
...

Sheet AOC 200G(Returned)
A1: 100G | B1: 200G | C1: 400G | E1: AOC
A2: WO | B2: Qty In | C2: Note | E2: Start Runcard | G2: AOC Assembly 1 | I2: AOC Assembly 2 | K2: AOC Assembly 3 | M2: AOC Baking | O2: AOC 20TC | Q2: AOC Post Test | S2: TCBer Test | U2: Packet Loss Test | W2: AOC Inspection | Y2: INVT PCS
A3: 120049614 | B3: 30 | C3: 200G | D3: Target Date | E3: 46070 | G3: =WORKDAY.INTL(E3,0,11) -> 46070 | I3: =WORKDAY.INTL(G3,0,11) -> 46070 | K3: =WORKDAY.INTL(I3,0,11) -> 46070 | M3: =WORKDAY.INTL(K3,0,11) -> 46070 | O3: =WORKDAY.INTL(M3,0,11) -> 46070 | Q3: =WORKDAY.INTL(O3,2,11) -> 46072 | S3: =WORKDAY.INTL(Q3,0,11) -> 46072 | U3: =WORKDAY.INTL(S3,0,11) -> 46072 | W3: =WORKDAY.INTL(U3,0,11) -> 46072 | Y3: =WORKDAY.INTL(W3,0,11) -> 46072
D4: Actual Date | E4: 46072
D5: WO In/Out | E5: 30
D6: Yield | E6: =F5/E5 -> 0 | G6: =H5/G5 -> #DIV/0! | I6: =J5/I5 -> #DIV/0! | K6: =L5/K5 -> #DIV/0! | M6: =N5/M5 -> #DIV/0! | O6: =P5/O5 -> #DIV/0! | Q6: =R5/Q5 -> #DIV/0! | S6: =T5/S5 -> #DIV/0! | U6: =V5/U5 -> #DIV/0! | W6: =X5/W5 -> #DIV/0! | Y6: =Z5/Y5 -> #DIV/0!
A7: 120049615 | B7: 30 | C7: 200G | D7: Target Date | E7: 46071 | G7: =WORKDAY.INTL(E7,0,11) -> 46071 | I7: =WORKDAY.INTL(G7,0,11) -> 46071 | K7: =WORKDAY.INTL(I7,0,11) -> 46071 | M7: =WORKDAY.INTL(K7,0,11) -> 46071 | O7: =WORKDAY.INTL(M7,0,11) -> 46071 | Q7: =WORKDAY.INTL(O7,2,11) -> 46073 | S7: =WORKDAY.INTL(Q7,0,11) -> 46073 | U7: =WORKDAY.INTL(S7,0,11) -> 46073 | W7: =WORKDAY.INTL(U7,0,11) -> 46073 | Y7: =WORKDAY.INTL(W7,0,11) -> 46073
D8: Actual Date | E8: 46072
D9: WO In/Out | E9: 30
D10: Yield | E10: =F9/E9 -> 0 | G10: =H9/G9 -> #DIV/0! | I10: =J9/I9 -> #DIV/0! | K10: =L9/K9 -> #DIV/0! | M10: =N9/M9 -> #DIV/0! | O10: =P9/O9 -> #DIV/0! | Q10: =R9/Q9 -> #DIV/0! | S10: =T9/S9 -> #DIV/0! | U10: =V9/U9 -> #DIV/0! | W10: =X9/W9 -> #DIV/0! | Y10: =Z9/Y9 -> #DIV/0!
A11: 120049616 | B11: 30 | C11: 200G | D11: Target Date | E11: 46072 | G11: =WORKDAY.INTL(E11,0,11) -> 46072 | I11: =WORKDAY.INTL(G11,0,11) -> 46072 | K11: =WORKDAY.INTL(I11,0,11) -> 46072 | M11: =WORKDAY.INTL(K11,0,11) -> 46072 | O11: =WORKDAY.INTL(M11,0,11) -> 46072 | Q11: =WORKDAY.INTL(O11,2,11) -> 46074 | S11: =WORKDAY.INTL(Q11,0,11) -> 46074 | U11: =WORKDAY.INTL(S11,0,11) -> 46074 | W11: =WORKDAY.INTL(U11,0,11) -> 46074 | Y11: =WORKDAY.INTL(W11,0,11) -> 46074
D12: Actual Date | E12: 46072
D13: WO In/Out | E13: 30
D14: Yield | E14: =F13/E13 -> 0 | G14: =H13/G13 -> #DIV/0! | I14: =J13/I13 -> #DIV/0! | K14: =L13/K13 -> #DIV/0! | M14: =N13/M13 -> #DIV/0! | O14: =P13/O13 -> #DIV/0! | Q14: =R13/Q13 -> #DIV/0! | S14: =T13/S13 -> #DIV/0! | U14: =V13/U13 -> #DIV/0! | W14: =X13/W13 -> #DIV/0! | Y14: =Z13/Y13 -> #DIV/0!
A15: 120049617 | B15: 30 | C15: 200G | D15: Target Date | E15: 46073 | G15: =WORKDAY.INTL(E15,0,11) -> 46073 | I15: =WORKDAY.INTL(G15,0,11) -> 46073 | K15: =WORKDAY.INTL(I15,0,11) -> 46073 | M15: =WORKDAY.INTL(K15,0,11) -> 46073 | O15: =WORKDAY.INTL(M15,0,11) -> 46073 | Q15: =WORKDAY.INTL(O15,2,11) -> 46076 | S15: =WORKDAY.INTL(Q15,0,11) -> 46076 | U15: =WORKDAY.INTL(S15,0,11) -> 46076 | W15: =WORKDAY.INTL(U15,0,11) -> 46076 | Y15: =WORKDAY.INTL(W15,0,11) -> 46076
D16: Actual Date
D17: WO In/Out | E17: 30
D18: Yield | E18: =F17/E17 -> 0 | G18: =H17/G17 -> #DIV/0! | I18: =J17/I17 -> #DIV/0! | K18: =L17/K17 -> #DIV/0! | M18: =N17/M17 -> #DIV/0! | O18: =P17/O17 -> #DIV/0! | Q18: =R17/Q17 -> #DIV/0! | S18: =T17/S17 -> #DIV/0! | U18: =V17/U17 -> #DIV/0! | W18: =X17/W17 -> #DIV/0! | Y18: =Z17/Y17 -> #DIV/0!
